<?xml version="1.0" ?>
<!-- =================================================================================== -->
<!-- |    This document was autogenerated by xacro from urdf/origin.xacro              | -->
<!-- |    EDITING THIS FILE BY HAND IS NOT RECOMMENDED                                 | -->
<!-- =================================================================================== -->
<robot
   name="wx200">
  <link name="robot_arm">
    <visual>
      <origin rpy="0 0 -1.570796325" xyz="0 0 0"/>
      <geometry>
        <mesh filename="meshes/base.stl" scale="1 1 1"/>
      </geometry>
      <material
        name="">
        <color
          rgba="0.3 0.3 0.3 1" />
      </material>
    </visual>
    <collision>
      <origin rpy="0 0 -1.570796325" xyz="0 0 0"/>
      <geometry>
        <mesh filename="meshes/base.stl" scale="1 1 1"/>
      </geometry>
    </collision>
    <inertial>
      <origin rpy="0 0 1.570796325" xyz="-0.0381747000 0.0006478630 0.0193458000"/>
      <mass value="0.540142"/>
      <inertia ixx="0.0021190000" iyy="0.0006925000" izz="0.0025280000" ixy="-0.0000172100" ixz="0.0000006389" iyz="0.0000461200"/>
    </inertial>
  </link>
  <joint name="waist" type="revolute">
    <axis xyz="0 0 1"/>
    <limit effort="8" lower="-3.14158265" upper="3.14158265" velocity="3.14159265"/>
    <origin rpy="0 0 0" xyz="0 0 0.072"/>
    <parent link="robot_arm"/>
    <child link="shoulder_link"/>
    <dynamics friction="0.1"/>
  </joint>
  <transmission name="trans_waist">
    <type>transmission_interface/SimpleTransmission</type>
    <joint name="waist">
      <hardwareInterface>hardware_interface/EffortJointInterface</hardwareInterface>
    </joint>
    <actuator name="waist_motor">
      <mechanicalReduction>1</mechanicalReduction>
    </actuator>
  </transmission>
  <link name="shoulder_link">
    <visual>
      <origin rpy="0 0 1.570796325" xyz="0 0 -0.003"/>
      <geometry>
        <mesh filename="meshes/wx200_2_shoulder.stl" scale="0.001 0.001 0.001"/>
      </geometry>
      <material
        name="">
        <color
          rgba="0.3 0.3 0.3 1" />
      </material>
    </visual>
    <collision>
      <origin rpy="0 0 1.570796325" xyz="0 0 -0.003"/>
      <geometry>
        <mesh filename="meshes/wx200_2_shoulder.stl" scale="0.001 0.001 0.001"/>
      </geometry>
    </collision>
    <inertial>
      <origin rpy="0 0 1.570796325" xyz="0.0000223210 0.0000414608 0.0066287000"/>
      <mass value="0.480879"/>
      <inertia ixx="0.0003790000" iyy="0.0005557000" izz="0.0005889000" ixy="0.0000000022" ixz="-0.0000003561" iyz="0.0000012247"/>
    </inertial>
  </link>
  <joint name="shoulder" type="revolute">
    <axis xyz="0 1 0"/>
    <limit effort="18" lower="-1.88496" upper="1.97222" velocity="3.14159265"/>
    <origin rpy="0 0 0" xyz="0 0 0.03865"/>
    <parent link="shoulder_link"/>
    <child link="upper_arm_link"/>
    <dynamics friction="0.1"/>
  </joint>
  <transmission name="trans_shoulder">
    <type>transmission_interface/SimpleTransmission</type>
    <joint name="shoulder">
      <hardwareInterface>hardware_interface/EffortJointInterface</hardwareInterface>
    </joint>
    <actuator name="shoulder_motor">
      <mechanicalReduction>1</mechanicalReduction>
    </actuator>
  </transmission>
  <link name="upper_arm_link">
    <visual>
      <origin rpy="0 0 1.570796325" xyz="0 0 0"/>
      <geometry>
        <mesh filename="meshes/wx200_3_upper_arm.stl" scale="0.001 0.001 0.001"/>
      </geometry>
      <material
        name="">
        <color
          rgba="0.3 0.3 0.3 1" />
      </material>
    </visual>
    <collision>
      <origin rpy="0 0 1.570796325" xyz="0 0 0"/>
      <geometry>
        <mesh filename="meshes/wx200_3_upper_arm.stl" scale="0.001 0.001 0.001"/>
      </geometry>
    </collision>
    <inertial>
      <origin rpy="0 0 1.570796325" xyz="0.0119707000 -0.0001179264 0.1394290000"/>
      <mass value="0.297781"/>
      <inertia ixx="0.0017100000" iyy="0.0016310000" izz="0.0001482000" ixy="-0.0000011433" ixz="0.0000021161" iyz="0.0002135000"/>
    </inertial>
  </link>
  <joint name="elbow" type="revolute">
    <axis xyz="0 1 0"/>
    <limit effort="13" lower="-1.88496" upper="1.62316" velocity="3.14159265"/>
    <origin rpy="0 0 0" xyz="0.05 0 0.2"/>
    <parent link="upper_arm_link"/>
    <child link="forearm_link"/>
    <dynamics friction="0.1"/>
  </joint>
  <transmission name="trans_elbow">
    <type>transmission_interface/SimpleTransmission</type>
    <joint name="elbow">
      <hardwareInterface>hardware_interface/EffortJointInterface</hardwareInterface>
    </joint>
    <actuator name="elbow_motor">
      <mechanicalReduction>1</mechanicalReduction>
    </actuator>
  </transmission>
  <link name="forearm_link">
    <visual>
      <origin rpy="0 0 1.570796325" xyz="0 0 0"/>
      <geometry>
        <mesh filename="meshes/wx200_4_forearm.stl" scale="0.001 0.001 0.001"/>
      </geometry>
      <material
        name="">
        <color
          rgba="0.3 0.3 0.3 1" />
      </material>
    </visual>
    <collision>
      <origin rpy="0 0 1.570796325" xyz="0 0 0"/>
      <geometry>
        <mesh filename="meshes/wx200_4_forearm.stl" scale="0.001 0.001 0.001"/>
      </geometry>
    </collision>
    <inertial>
      <origin rpy="0 0 1.570796325" xyz="0.1211920000 -0.0001238123 0.0000000000"/>
      <mass value="0.283651"/>
      <inertia ixx="0.0011850000" iyy="0.0000682900" izz="0.0012060000" ixy="-0.0000024317" ixz="0.0000000000" iyz="0.0000000000"/>
    </inertial>
  </link>
  <joint name="wrist_angle" type="revolute">
    <axis xyz="0 1 0"/>
    <limit effort="5" lower="-1.74533" upper="2.14675" velocity="3.14159265"/>
    <origin rpy="0 0 0" xyz="0.2 0 0"/>
    <parent link="forearm_link"/>
    <child link="wrist_link"/>
    <dynamics friction="0.1"/>
  </joint>
  <transmission name="trans_wrist_angle">
    <type>transmission_interface/SimpleTransmission</type>
    <joint name="wrist_angle">
      <hardwareInterface>hardware_interface/EffortJointInterface</hardwareInterface>
    </joint>
    <actuator name="wrist_angle_motor">
      <mechanicalReduction>1</mechanicalReduction>
    </actuator>
  </transmission>
  <link name="wrist_link">
    <visual>
      <origin rpy="0 0 1.570796325" xyz="0 0 0"/>
      <geometry>
        <mesh filename="meshes/wx200_5_wrist.stl" scale="0.001 0.001 0.001"/>
      </geometry>
      <material
        name="">
        <color
          rgba="0.3 0.3 0.3 1" />
      </material>
    </visual>
    <collision>
      <origin rpy="0 0 1.570796325" xyz="0 0 0"/>
      <geometry>
        <mesh filename="meshes/wx200_5_wrist.stl" scale="0.001 0.001 0.001"/>
      </geometry>
    </collision>
    <inertial>
      <origin rpy="0 0 1.570796325" xyz="0.0423600000 -0.0000106630 0.0105770000"/>
      <mass value="0.084957"/>
      <inertia ixx="0.0000308200" iyy="0.0000282200" izz="0.0000315200" ixy="0.0000000191" ixz="0.0000000023" iyz="0.0000025481"/>
    </inertial>
  </link>
  <joint name="wrist_rotate" type="revolute">
    <axis xyz="1 0 0"/>
    <limit effort="1" lower="-3.14158265" upper="3.14158265" velocity="3.14159265"/>
    <origin rpy="0 0 0" xyz="0.065 0 0"/>
    <parent link="wrist_link"/>
    <child link="gripper_link"/>
    <dynamics friction="0.1"/>
  </joint>
  <transmission name="trans_wrist_rotate">
    <type>transmission_interface/SimpleTransmission</type>
    <joint name="wrist_rotate">
      <hardwareInterface>hardware_interface/EffortJointInterface</hardwareInterface>
    </joint>
    <actuator name="wrist_rotate_motor">
      <mechanicalReduction>1</mechanicalReduction>
    </actuator>
  </transmission>
  <link name="gripper_link">
    <visual>
      <origin rpy="0 0 1.570796325" xyz="-0.02 0 0"/>
      <geometry>
        <mesh filename="meshes/wx200_6_gripper.stl" scale="0.001 0.001 0.001"/>
      </geometry>
      <material
        name="">
        <color
          rgba="0.3 0.3 0.3 1" />
      </material>
    </visual>
    <collision>
      <origin rpy="0 0 1.570796325" xyz="-0.02 0 0"/>
      <geometry>
        <mesh filename="meshes/wx200_6_gripper.stl" scale="0.001 0.001 0.001"/>
      </geometry>
    </collision>
    <inertial>
      <origin rpy="0 0 1.570796325" xyz="0.0216310000 0.0000002516 0.0114100000"/>
      <mass value="0.072885"/>
      <inertia ixx="0.0000253700" iyy="0.0000183600" izz="0.0000167400" ixy="0.0000000000" ixz="0.0000000000" iyz="0.0000004340"/>
    </inertial>
  </link>
  <joint name="ee_arm" type="fixed">
    <axis xyz="1 0 0"/>
    <origin rpy="0 0 0" xyz="0.043 0 0"/>
    <parent link="gripper_link"/>
    <child link="ee_arm_link"/>
  </joint>
  <link name="ee_arm_link">
    <inertial>
      <mass value="0.001"/>
      <inertia ixx="0.001" iyy="0.001" izz="0.001" ixy="0" ixz="0" iyz="0"/>
    </inertial>
  </link>
  <link
    name="gripper_bar">
    <inertial>
      <origin
        xyz="0.0077886 -0.00065929 0.0023098"
        rpy="0 0 0" />
      <mass
        value="0.030878" />
      <inertia
        ixx="0.1"
        ixy="0"
        ixz="0"
        iyy="0.1"
        iyz="0"
        izz="0.1" />
    </inertial>
    <visual>
      <origin
        xyz="0 0 0"
        rpy="0 0 0" />
      <geometry>
        <mesh
          filename="meshes/gripper_bar.STL" />
      </geometry>
      <material
        name="">
        <color
          rgba="0.3 0.3 0.3 1" />
      </material>
    </visual>
    <collision>
      <origin
        xyz="0 0 0"
        rpy="0 0 0" />
      <geometry>
        <mesh
          filename="meshes/gripper_bar.STL" />
      </geometry>
    </collision>
  </link>
  <joint
    name="g_par2motor"
    type="fixed">
    <origin
      xyz="0.004 0 0"
      rpy="0 0 0" />
    <parent
      link="ee_arm_link" />
    <child
      link="gripper_bar" />
    <axis
      xyz="0 0 0" />
  </joint>
  <link
    name="left_gripper">
    <contact>
      <friction_anchor/>
      <stiffness value="30000.0"/>
      <damping value="1000.0"/>
      <spinning_friction value="0.1"/>
      <lateral_friction value="1.0"/>
    </contact>
    <inertial>
      <origin
        xyz="-0.01704 0.009464 0"
        rpy="0 0 0" />
      <mass
        value="0.013875" />
      <inertia
        ixx="0.1"
        ixy="0"
        ixz="0"
        iyy="0.1"
        iyz="0"
        izz="0.1" />
    </inertial>
    <visual>
      <origin
        xyz="-0.028 0 0"
        rpy="0 0 0" />
      <geometry>
        <box size="0.030 0.005 0.03"/>
      </geometry>
      <material
        name="">
        <color
          rgba="0.3 0.3 0.3 1" />
      </material>
      <material
        name="">
        <color
          rgba="0.3 0.3 0.3 1" />
      </material>
    </visual>
    <collision>
      <origin
        xyz="-0.028 0 0"
        rpy="0 0 0" />
      <geometry>
        <box size="0.030 0.005 0.03"/>
      </geometry>
      <material
        name="">
        <color
          rgba="0.3 0.3 0.3 1" />
      </material>
    </collision>
  </link>
  <joint
    name="left_gripper2bar"
    type="prismatic">
    <origin
      xyz="0.018 0.036991 0"
      rpy="0 0 -3.1416" />
    <parent
      link="gripper_bar" />
    <child
      link="left_gripper" />
    <axis
      xyz="0 1 0" />
    <limit
      lower="0"
      upper="0.03202"
      effort="20"
      velocity="0.2" />
  </joint>
  <link
    name="right_gripper">
    <contact>
      <friction_anchor/>
      <stiffness value="30000.0"/>
      <damping value="1000.0"/>
      <spinning_friction value="0.1"/>
      <lateral_friction value="1.0"/>
    </contact>
    <inertial>
      <origin
        xyz="0.01704 0.009464 0"
        rpy="0 0 0" />
      <mass
        value="0.013875" />
      <inertia
        ixx="0.1"
        ixy="0"
        ixz="0"
        iyy="0.1"
        iyz="0"
        izz="0.1" />
    </inertial>
    <visual>
      <origin
        xyz="-0.028 0 0"
        rpy="0 0 0" />
      <geometry>
        <box size="0.030 0.005 0.03"/>
      </geometry>
      <material
        name="">
        <color
          rgba="0.3 0.3 0.3 1" />
      </material>
    </visual>
    <collision>
      <origin
        xyz="-0.028 0 0"
        rpy="0 0 0" />
      <geometry>
        <box size="0.030 0.005 0.03"/>
      </geometry>
    </collision>
  </link>
  <joint
    name="right_gripper2bar"
    type="prismatic">
    <origin
      xyz="0.018 -0.036991 0"
      rpy="0 3.1416 0" />
    <parent
      link="gripper_bar" />
    <child
      link="right_gripper" />
    <axis
      xyz="0 1 0" />
    <limit
      lower="0"
      upper="0.03202"
      effort="20"
      velocity="0.2" />
  </joint>
  <joint name="ee_gripper" type="fixed">
    <axis xyz="1 0 0"/>
    <origin rpy="0 0 0" xyz="0.061 0 0"/>
    <parent link="gripper_bar"/>
    <child link="ee_gripper_link"/>
  </joint>
  <link name="ee_gripper_link">
    <inertial>
      <mass value="0"/>
      <inertia ixx="0.001" iyy="0.001" izz="0.001" ixy="0" ixz="0" iyz="0"/>
    </inertial>
    <visual>
      <origin
        xyz="0 0 0"
        rpy="0 0 0" />
      <geometry>
        <box size="0.002 0.002 0.002"/>
      </geometry>
      <material
        name="">
        <color
          rgba="0.3 0.3 0.3 1" />
      </material>
    </visual>
  </link>
</robot>
